---
title: "**Understanding CompletionException in Java**"
date: 2024-10-30 09:00:00 -0000
categories: [Java, java.base]
tags: [java, java-unchecked, java.util.concurrent, java-se]
mermaid: true
toc: true
---


Are you struggling with handling exceptions in asynchronous programming? Look no further! In this article, we will dive deep into the world of CompletionException in Java and learn how it can help you simplify error handling in your asynchronous code. So grab your cup of coffee and get ready for the next 15 minutes of enlightening information.

## What is CompletionException?

CompletionException is a class provided by the Java API that extends the RuntimeException class. It represents an exceptional result of a computation that failed to complete normally. In the context of asynchronous programming, it is often used to wrap checked exceptions thrown during the execution of a CompletableFuture.

## The Need for CompletionException

Before Java 8, handling exceptions in asynchronous programming was quite cumbersome. Whenever an exception occurred during the execution of a CompletableFuture, it had to be manually caught and rethrown from within a callback. This approach not only cluttered the code but also made exception handling error-prone.

To tackle this issue, Java 8 introduced CompletableFuture which provides a clean and elegant way to deal with exceptions thrown during asynchronous computations. And CompletionException plays a pivotal role in achieving this.

## How CompletionException Works

When an exception occurs during the execution of a CompletableFuture, it is automatically wrapped in a CompletionException. This allows exceptions to flow through the asynchronous chain, regardless of whether they are unchecked or checked exceptions. 

Let's take a look at an example that demonstrates the usage of CompletionException:

```java
CompletableFuture<Integer> future = CompletableFuture.supplyAsync(() -> {
    // Some code that may throw an exception
    return someValue;
});

future.exceptionally(ex -> {
    if (ex instanceof CompletionException) {
        ex = ex.getCause();
    }
    
    // Handle the exception
    return defaultValue;
});
```

In the above example, if an exception occurs within the `supplyAsync` method, it will be automatically wrapped in a CompletionException. The `exceptionally` method allows us to handle the exception, and by unwrapping the CompletionException using `getCause()`, we can access the actual cause of the exception.

The beauty of CompletionException is that it solves the problem of checked exceptions not being allowed to propagate through the CompletableFuture chain. By wrapping checked exceptions in CompletionException, they can now be handled consistently without any additional boilerplate code.

## Best Practices for Using CompletionException

To make the most out of CompletionException, consider the following best practices:

### 1. Use exception chaining

Whenever an exception is wrapped in a CompletionException, it is important to preserve the original cause. This can be achieved by passing the cause Exception to the constructor of the CompletionException:

```java
Throwable cause = new SomeCheckedException("Something went wrong");
throw new CompletionException(cause);
```

By preserving the cause, it becomes easier to debug and troubleshoot issues that occur within the asynchronous code.

### 2. Use explicit exception handling

While CompletionException provides a convenient way to handle exceptions, it is generally recommended to combine it with explicit exception handling within the CompletableFuture chain. This allows for greater control over error handling and makes the code more readable and maintainable.

```java
CompletableFuture<Integer> future = CompletableFuture.supplyAsync(() -> {
    // Some code that may throw an exception
    return someValue;
});

future.handle((value, ex) -> {
    if (ex != null) {
        if (ex instanceof CompletionException) {
            ex = ex.getCause();
        }
        
        // Handle the exception
        return defaultValue;
    }
    
    // Handle the result
    return value;
});
```

By using the `handle` method instead of `exceptionally`, both the result and exception can be handled within the same callback. This promotes cleaner code and removes the need for multiple callback methods.

### 3. Be cautious with multiple levels of CompletionException

When working with nested CompletableFuture chains, it is important to be cautious with multiple levels of CompletionException. If not handled properly, it can lead to confusion and make debugging more complex.

To avoid this, it is recommended to handle each level of CompletableFuture independently and unwrap any CompletionExceptions before propagating them to the next level.

## Conclusion

CompletionException is a powerful feature introduced in Java 8 that simplifies exception handling in asynchronous programming. By automatically wrapping exceptions and allowing them to flow through the CompletableFuture chain, it greatly improves the readability and maintainability of code.

In this article, we covered the basics of CompletionException, how it works, and best practices for its usage. Now you have the knowledge to handle exceptions in asynchronous code like a pro. So go ahead, embrace CompletionException, and create more robust and efficient asynchronous applications in Java.

If you want to learn more about CompletionException, check out the official Oracle documentation: [CompletableFuture API Documentation](https://docs.oracle.com/en/java/javase/11/docs/api/java.base/java/util/concurrent/CompletionException.html).

Happy coding!