---
title: "Title: The Comprehensive Guide to ExecutionException in Java - Understanding Its Causes and Finding Effective Solutions"
date: 2024-06-28 09:00:00 -0000
categories: [Java, java.base]
tags: [java, java-unchecked, java.util.concurrent, java-se]
mermaid: true
toc: true
---


## Introduction

In the world of Java programming, exceptions are an integral part of ensuring the smooth execution of code. However, encountering an `ExecutionException` can be quite daunting for even experienced developers. This guide aims to demystify the concept of `ExecutionException` and its causes, enabling you to handle these exceptions with confidence.

## What is ExecutionException?

The `ExecutionException` is a checked exception that extends `Exception` and is part of the `java.util.concurrent` package in Java. It is thrown when a task being executed by an `ExecutorService` encounters an exception.

The `ExecutorService` framework, introduced in Java 5, allows developers to manage the execution of tasks asynchronously. It provides a way to execute tasks concurrently, enabling better utilization of system resources. However, when a task encounters an exception and the `Future` object is queried to retrieve the result or exception, an `ExecutionException` occurs.

## Causes of ExecutionException

1. **Unchecked Exception**: One common cause of `ExecutionException` is when an unchecked exception, such as `NullPointerException` or `ArrayIndexOutOfBoundsException`, occurs during task execution. As these exceptions are not explicitly handled within the task, they get propagated to the `Future` object, resulting in an `ExecutionException`.

   ```java
   ExecutorService executorService = Executors.newFixedThreadPool(5);
   Future<Integer> future = executorService.submit(() -> {
       int dividend = 10;
       int divisor = 0;
       return dividend / divisor; // Throws ArithmeticException
   });

   try {
       Integer result = future.get();
   } catch (ExecutionException e) {
       // Handle ExecutionException caused by ArithmeticException
   }
   ```

2. **Exception Thrown within Callable**: Another cause of `ExecutionException` is when a checked exception is thrown within the `call()` method of a `Callable` object. When the `call()` method throws an exception, it is wrapped in an `ExecutionException` by the `Future` object.

   ```java
   ExecutorService executorService = Executors.newFixedThreadPool(5);
   Future<String> future = executorService.submit(() -> {
       throw new IOException("File not found"); // Throws IOException
   });

   try {
       String result = future.get();
   } catch (ExecutionException e) {
       // Handle ExecutionException caused by IOException
   }
   ```

3. **Exception while Retrieving the Result**: A third cause of `ExecutionException` is when an exception occurs while trying to retrieve the result of a `Future` object. This can happen if you invoke the `get()` method on a `Future` object before the task has completed or if the task was cancelled before completion. In such cases, the `ExecutionException` wraps the original `CancellationException` or `InterruptedException` respectively.

   ```java
   ExecutorService executorService = Executors.newFixedThreadPool(5);
   Future<String> future = executorService.submit(() -> {
       // Task execution
   });

   try {
       Thread.sleep(5000); // Simulating delay
       String result = future.get(); // Throws InterruptedException
   } catch (ExecutionException e) {
       // Handle ExecutionException caused by InterruptedException
   }
   ```

## Handling ExecutionException

When dealing with `ExecutionException`, it is crucial to separate the original cause from the wrapper exception. The `ExecutionException` provides methods to access the root cause using the `getCause()` or `getLocalizedMessage()` methods. Here's an example illustrating how to handle a `ExecutionException` gracefully:

```java
ExecutorService executorService = Executors.newFixedThreadPool(5);
Future<Integer> future = executorService.submit(() -> {
   // Task execution that may throw an exception
});

try {
   Integer result = future.get();
   // Process the result
} catch (InterruptedException e) {
   // Handle InterruptedException
} catch (ExecutionException e) {
   Throwable cause = e.getCause(); // Get the root cause
   if (cause instanceof ArithmeticException) {
       // Handle ArithmeticException
   } else if (cause instanceof IOException) {
       // Handle IOException
   } else {
       // Handle other exceptions
   }
}
```

## Conclusion

In this guide, we explored the concept of `ExecutionException` in Java and identified its causes. We learned that `ExecutionException` occurs when a task being executed by an `ExecutorService` encounters an exception. By understanding the different scenarios and handling `ExecutionException` effectively, you can ensure the robustness of your concurrent Java applications.

Keep in mind that preventing exceptions where possible, employing fault-tolerant coding practices, and understanding the behavior of your tasks can significantly reduce the occurrence of `ExecutionException` in your code.

To delve deeper into exception handling and concurrent programming in Java, feel free to explore the following resources:

- [Java ExecutorService Documentation](https://docs.oracle.com/en/java/javase/11/docs/api/java.base/java/util/concurrent/ExecutorService.html)
- [Java Future Documentation](https://docs.oracle.com/en/java/javase/11/docs/api/java.base/java/util/concurrent/Future.html)
- [Java Callable Documentation](https://docs.oracle.com/en/java/javase/11/docs/api/java.base/java/util/concurrent/Callable.html)

Happy coding!

*Estimated reading time: 15 minutes*