---
title: "NameAlreadyBoundException in Java: A Comprehensive Guide "
date: 2024-03-29 09:00:00 -0000
categories: [Java, java.naming]
tags: [java, java-checked, javax.naming, java-se]
mermaid: true
toc: true
---


As a Java developer, you may have encountered various exceptions while coding. In this article, we will explore one such exception called `NameAlreadyBoundException`. We will discuss what this exception is, when it occurs, and how to handle it effectively in your Java applications. So, let's dive in!

## What is `NameAlreadyBoundException`?

`NameAlreadyBoundException` is a checked exception that belongs to the `javax.naming` package in Java. This exception is thrown to indicate that an object with the specified name is already bound in the naming context. In other words, it signals that a naming collision has occurred when attempting to bind a new object with a name that is already in use.

## Understanding the Context of `NameAlreadyBoundException`

To understand the `NameAlreadyBoundException`, let's first explore the concept of naming context in Java. A naming context, represented by the `javax.naming.Context` class, provides a hierarchical structure for organizing and accessing named objects. It acts as a directory service, allowing you to bind, rebind, and unbind objects by their names.

The `bind()` method in the `Context` class is used to bind an object to a specific name in the naming context. When you invoke this method, Java checks if the specified name is already bound to an object in the context. If it is, a `NameAlreadyBoundException` is thrown.

## When Does `NameAlreadyBoundException` Occur?

Let's take a look at a code example to understand when the `NameAlreadyBoundException` occurs:

```java
import javax.naming.Context;
import javax.naming.InitialContext;
import javax.naming.NameAlreadyBoundException;

public class NamingExample {
    public static void main(String[] args) {
        try {
            // Create a new naming context
            Context context = new InitialContext();
            
            // Bind an object to a name
            context.bind("myObject", new MyObject());
            
            // Attempt to bind another object with the same name
            context.bind("myObject", new AnotherObject());
        } catch (NameAlreadyBoundException e) {
            System.out.println("The name is already bound to an object.");
        } catch (Exception e) {
            e.printStackTrace();
        }
    }
}

class MyObject {
    // MyObject implementation here
}

class AnotherObject {
    // AnotherObject implementation here
}
```

In the above example, we are creating a new naming context and binding an object of `MyObject` to the name `"myObject"`. However, when we attempt to bind another object of `AnotherObject` with the same name, a `NameAlreadyBoundException` is thrown.

## Handling `NameAlreadyBoundException`

To handle the `NameAlreadyBoundException`, you can use a try-catch block. In the catch block, you can perform appropriate error handling or display a meaningful message to the user.

Here's an improved version of the previous code example that demonstrates how to handle the exception:

```java
import javax.naming.Context;
import javax.naming.InitialContext;
import javax.naming.NameAlreadyBoundException;

public class NamingExample {
    public static void main(String[] args) {
        try {
            // Create a new naming context
            Context context = new InitialContext();
            
            // Bind an object to a name
            context.bind("myObject", new MyObject());
            
            // Attempt to bind another object with the same name
            context.bind("myObject", new AnotherObject());
        } catch (NameAlreadyBoundException e) {
            System.err.println("Failed to bind object: The name is already bound to an object.");
        } catch (Exception e) {
            e.printStackTrace();
        }
    }
}

class MyObject {
    // MyObject implementation here
}

class AnotherObject {
    // AnotherObject implementation here
}
```

In the above code, we catch the `NameAlreadyBoundException` specifically and print a meaningful error message to the standard error stream.

## Conclusion

In this article, we explored the `NameAlreadyBoundException` in Java. We discussed its definition, when it occurs, and how to handle it effectively in your Java applications. By understanding this exception, you can ensure smooth execution of your code when working with naming contexts. Remember to handle the exception gracefully and provide informative error messages to enhance user experience.

Keep coding and conquering exceptions!

## References

- [Java Naming and Directory Interface (JNDI) - Oracle Documentation](https://docs.oracle.com/en/java/javase/11/docs/api/jdk.naming.jndi-summary.html)
- [Exception Hierarchy in Java - Oracle Documentation](https://docs.oracle.com/en/java/javase/11/docs/api/java.base/java/lang/Exception.html)